Workbook

Sheet Personal Stats
A1: AGL | B1: ATT | C1: CON | D1: COOK | E1: CRAFT | F1: DEF | G1: FARM | H1: FM | I1: FISH | J1: FLETCH | K1: HERB | L1: HUNT | M1: MAGE | N1: MINING | O1: PRAY | P1: RANGE | Q1: RC | R1: SAIL | S1: SLAY | T1: SMITH | U1: STR | V1: THEIF | W1: WC | X1: Quest Points | Y1: Combat
A2: 45 | B2: 60 | C2: 52 | D2: 66 | E2: 50 | F2: 70 | G2: 52 | H2: 66 | I2: 62 | J2: 52 | K2: 54 | L2: 42 | M2: 67 | N2: 51 | O2: 70 | P2: 75 | Q2: 23 | R2: 48 | S2: 47 | T2: 53 | U2: 70 | V2: 54 | W2: 60 | X2: 191 | Y2: 86
A13: 5 | B13: Animal Magnetism | E13: Animal Magnetism | F13: =IFERROR(ADDRESS(MATCH(E13, $B$13:$B$24, 0) + 12, COLUMN(B1)), "Not Found") -> $B$13
A14: 6 | B14: Another Slice of H.A.M. | E14: Another Slice of H.A.M. | F14: =IFERROR(ADDRESS(MATCH(E14, $B$13:$B$24, 0) + 12, COLUMN(B2)), "Not Found") -> $B$14
A15: 7 | B15: Between a Rock… | E15: Between a Rock… | F15: =IFERROR(ADDRESS(MATCH(E15, $B$13:$B$24, 0) + 12, COLUMN(B3)), "Not Found") -> $B$15
A16: 8 | B16: Big Chompy Bird Hunting | E16: Big Chompy Bird Hunting | F16: =IFERROR(ADDRESS(MATCH(E16, $B$13:$B$24, 0) + 12, COLUMN(B4)), "Not Found") -> $B$16
A17: 9 | B17: Biohazard | E17: Biohazard | F17: =IFERROR(ADDRESS(MATCH(E17, $B$13:$B$24, 0) + 12, COLUMN(B5)), "Not Found") -> $B$17
A18: 10 | B18: Black Knight's Fortress | E18: Black Knight's Fortress | F18: =IFERROR(ADDRESS(MATCH(E18, $B$13:$B$24, 0) + 12, COLUMN(B6)), "Not Found") -> $B$18
A19: 11 | B19: Cabin Fever | E19: Cabin Fever | F19: =IFERROR(ADDRESS(MATCH(E19, $B$13:$B$24, 0) + 12, COLUMN(B7)), "Not Found") -> $B$19
A20: 12 | B20: Clock Tower | E20: Clock Tower | F20: =IFERROR(ADDRESS(MATCH(E20, $B$13:$B$24, 0) + 12, COLUMN(B8)), "Not Found") -> $B$20
A21: 13 | B21: Cold War | E21: Cold War | F21: =IFERROR(ADDRESS(MATCH(E21, $B$13:$B$24, 0) + 12, COLUMN(B9)), "Not Found") -> $B$21
A22: 14 | B22: Contact! | E22: Contact! | F22: =IFERROR(ADDRESS(MATCH(E22, $B$13:$B$24, 0) + 12, COLUMN(B10)), "Not Found") -> $B$22
A23: 15 | B23: Cook's Assistant | E23: Cook's Assistant | F23: =IFERROR(ADDRESS(MATCH(E23, $B$13:$B$24, 0) + 12, COLUMN(B11)), "Not Found") -> $B$23
A24: 16 | B24: Creature of Fenkenstrain | E24: Creature of Fenkenstrain | F24: =IFERROR(ADDRESS(MATCH(E24, $B$13:$B$24, 0) + 12, COLUMN(B12)), "Not Found") -> $B$24
A25: 17 | B25: Darkness of Hallowvale
A26: 18 | B26: Death Plateau
A27: 19 | B27: Death to the Dorgeshuun
A28: 20 | B28: Demon Slayer
A29: 21 | B29: Desert Treasure
A30: 22 | B30: Devious Minds
A31: 23 | B31: Digsite, The
A32: 24 | B32: Doric's Quest
A33: 25 | B33: Dragon Slayer
A34: 26 | B34: Dream Mentor
A35: 27 | B35: Druidic Ritual
A36: 28 | B36: Dwarf Cannon
... A188: 180 | B188: Troubled Tortugans

Sheet Normal Runescape Quest Guide
F1: Agil | G1: Att | H1: Con | I1: Cook | J1: Craft | K1: Def | L1: Farm | M1: FM | N1: Fish | O1: Fletch | P1: Herb | Q1: Hunt | R1: Magic | S1: Mine | T1: Pray | U1: Range | V1: RC | W1: Sailing | X1: Slay | Y1: Smith | Z1: Str | AA1: Thieve | AB1: WC | AC1: QP | AD1: Combat | AE1: Levels Needed
F2: ='Personal Stats'!A2 -> 45 | G2: ='Personal Stats'!B2 -> 60 | H2: ='Personal Stats'!C2 -> 52 | I2: ='Personal Stats'!D2 -> 66 | J2: ='Personal Stats'!E2 -> 50 | K2: ='Personal Stats'!F2 -> 70 | L2: ='Personal Stats'!G2 -> 52 | M2: ='Personal Stats'!H2 -> 66 | ... AD2: ='Personal Stats'!Y2 -> 86
A4: Quest | B4: Available? | C4: Complete? | D4: Pre-Req? | E4: Stats? | F4: Agil | G4: Att | H4: Con | I4: Cook | J4: Craft | K4: Def | L4: Farm | M4: FM | N4: Fish | O4: Fletch | P4: Herb | Q4: Hunt | R4: Magic | S4: Mine | T4: Pray | U4: Range | V4: RC | W4: Sailing | X4: Slay | Y4: Smith | Z4: Str | AA4: Thieve | AB4: WC | AC4: QP | AD4: Combat
A5: Animal Magnetism | B5: =AND(D5=TRUE(),E5=TRUE()) -> TRUE | C5: Y | D5: =TRUE() -> TRUE | E5: =SUMPRODUCT((F5:AD5 <> "") * (F5:AD5 < F$2:AD$2)) = 4 -> TRUE | J5: 19 | U5: 30 | X5: 18 | AB5: 35 | AE5: =SUMPRODUCT((F5:AA5 - $F$2:$AA$2) * ((F5:AA5 - $F$2:$AA$2) > 0)) -> 0 | AJ5: Animal Magnetism | AK5: =IFERROR(ADDRESS(MATCH(AJ5, $A$5:$A$180, 0) + 4, COLUMN(A1)), "Not Found") -> $A$5
A6: Another Slice of H.A.M. | B6: =AND(D6=TRUE(),E6=TRUE()) -> FALSE | C6: N | D6: =AND(INDEX(C:C, MATCH("Death to the Dorgeshuun", AJ:AJ, 0)) = "Y",INDEX(C:C, MATCH("Giant Dwarf, The", AJ:AJ, 0)) = "Y",INDEX(C:C, MATCH("Digsite, The", AJ:AJ, 0)) = "Y") -> FALSE | E6: =SUMPRODUCT((F6:AD6 <> "") * (F6:AD6 < F$2:AD$2)) = 2 -> TRUE | G6: 15 | T6: 25 | AE6: =SUMPRODUCT((F6:AA6 - $F$2:$AA$2) * ((F6:AA6 - $F$2:$AA$2) > 0)) -> 0 | AJ6: Another Slice of H.A.M. | AK6: =IFERROR(ADDRESS(MATCH(AJ6, $A$5:$A$180, 0) + 4, COLUMN(A2)), "Not Found") -> $A$6
A7: Between a Rock… | B7: =AND(D7=TRUE(),E7=TRUE()) -> TRUE | C7: Y | D7: =AND(INDEX(C:C, MATCH("Dwarf Cannon", AJ:AJ, 0)) = "Y",INDEX(C:C, MATCH("Fishing Contest", AJ:AJ, 0)) = "Y") -> TRUE | E7: =SUMPRODUCT((F7:AD7 <> "") * (F7:AD7 < F$2:AD$2)) = 3 -> TRUE | K7: 30 | S7: 40 | Y7: 50 | AE7: =SUMPRODUCT((F7:AA7 - $F$2:$AA$2) * ((F7:AA7 - $F$2:$AA$2) > 0)) -> 0 | AJ7: Between a Rock… | AK7: =IFERROR(ADDRESS(MATCH(AJ7, $A$5:$A$180, 0) + 4, COLUMN(A3)), "Not Found") -> $A$7
A8: Big Chompy Bird Hunting | B8: =AND(D8=TRUE(),E8=TRUE()) -> FALSE | C8: Y | D8: =TRUE() -> TRUE | E8: =SUMPRODUCT((F8:AD8 <> "") * (F8:AD8 < F$2:AD$2)) = 4 -> 0 | I8: 30 | O8: 5 | U8: 30 | AE8: =SUMPRODUCT((F8:AA8 - $F$2:$AA$2) * ((F8:AA8 - $F$2:$AA$2) > 0)) -> 0 | AJ8: Big Chompy Bird Hunting | AK8: =IFERROR(ADDRESS(MATCH(AJ8, $A$5:$A$180, 0) + 4, COLUMN(A4)), "Not Found") -> $A$8
A9: Black Knight's Fortress | B9: =AND(D9=TRUE(),E9=TRUE()) -> TRUE | C9: Y | D9: =AND(INDEX(C:C, MATCH("Plague City", AJ:AJ, 0)) = "Y") -> TRUE | E9: =SUMPRODUCT((F9:AD9 <> "") * (F9:AD9 < F$2:AD$2)) = 1 -> TRUE | R9: 33 | AE9: =SUMPRODUCT((F9:AA9 - $F$2:$AA$2) * ((F9:AA9 - $F$2:$AA$2) > 0)) -> 0 | AJ9: Black Knight's Fortress | AK9: =IFERROR(ADDRESS(MATCH(AJ9, $A$5:$A$180, 0) + 4, COLUMN(A5)), "Not Found") -> $A$9
A10: Black Knight's Fortress | B10: =AND(D10=TRUE(),E10=TRUE()) -> TRUE | C10: Y | D10: =TRUE() -> TRUE | E10: =SUMPRODUCT((F10:AD10 <> "") * (F10:AD10 < F$2:AD$2)) = 0 -> TRUE | AE10: =SUMPRODUCT((F10:AA10 - $F$2:$AA$2) * ((F10:AA10 - $F$2:$AA$2) > 0)) -> 0 | AJ10: Black Knight's Fortress | AK10: =IFERROR(ADDRESS(MATCH(AJ10, $A$5:$A$180, 0) + 4, COLUMN(A6)), "Not Found") -> $A$9
A11: Cabin Fever | B11: =AND(D11=TRUE(),E11=TRUE()) -> TRUE | C11: Y | D11: =AND(INDEX(C:C, MATCH("Pirate's Treasure", AJ:AJ, 0)) = "Y", INDEX(C:C, MATCH("Rum Deal", AJ:AJ, 0)) = "Y") -> TRUE | E11: =SUMPRODUCT((F11:AD11 <> "") * (F11:AD11 < F$2:AD$2)) = 4 -> 1 | F11: 42 | J11: 45 | U11: 40 | Y11: 50 | AE11: =SUMPRODUCT((F11:AA11 - $F$2:$AA$2) * ((F11:AA11 - $F$2:$AA$2) > 0)) -> 0 | AJ11: Cabin Fever | AK11: =IFERROR(ADDRESS(MATCH(AJ11, $A$5:$A$180, 0) + 4, COLUMN(A7)), "Not Found") -> $A$11
A12: Clock Tower | B12: =AND(D12=TRUE(),E12=TRUE()) -> TRUE | C12: Y | D12: =TRUE() -> TRUE | E12: =SUMPRODUCT((F12:AD12 <> "") * (F12:AD12 < F$2:AD$2)) = 0 -> TRUE | AE12: =SUMPRODUCT((F12:AA12 - $F$2:$AA$2) * ((F12:AA12 - $F$2:$AA$2) > 0)) -> 0 | AJ12: Clock Tower | AK12: =IFERROR(ADDRESS(MATCH(AJ12, $A$5:$A$180, 0) + 4, COLUMN(A8)), "Not Found") -> $A$12
A13: Cold War | B13: =AND(D13=TRUE(),E13=TRUE()) -> TRUE | C13: N | D13: =TRUE() -> TRUE | E13: =SUMPRODUCT((F13:AD13 <> "") * (F13:AD13 < F$2:AD$2)) = 4 -> 1 | F13: 30 | H13: 34 | J13: 30 | Q13: 10 | AE13: =SUMPRODUCT((F13:AA13 - $F$2:$AA$2) * ((F13:AA13 - $F$2:$AA$2) > 0)) -> 0 | AJ13: Cold War | AK13: =IFERROR(ADDRESS(MATCH(AJ13, $A$5:$A$180, 0) + 4, COLUMN(A9)), "Not Found") -> $A$13
A14: Contact! | B14: =AND(D14=TRUE(),E14=TRUE()) -> TRUE | C14: N | D14: =AND(INDEX(C:C, MATCH("Prince Ali Rescue", AJ:AJ, 0)) = "Y",INDEX(C:C, MATCH("Gertrude's Cat", AJ:AJ, 0)) = "Y",INDEX(C:C, MATCH("Icthlarin's Little Helper", AJ:AJ, 0)) = "Y") -> TRUE | E14: =SUMPRODUCT((F14:AD14 <> "") * (F14:AD14 < F$2:AD$2)) = 0 -> TRUE | AE14: =SUMPRODUCT((F14:AA14 - $F$2:$AA$2) * ((F14:AA14 - $F$2:$AA$2) > 0)) -> 0 | AJ14: Contact! | AK14: =IFERROR(ADDRESS(MATCH(AJ14, $A$5:$A$180, 0) + 4, COLUMN(A10)), "Not Found") -> $A$14
A15: Cook's Assistant | B15: =AND(D15=TRUE(),E15=TRUE()) -> TRUE | C15: Y | D15: =TRUE() -> TRUE | E15: =SUMPRODUCT((F15:AD15 <> "") * (F15:AD15 < F$2:AD$2)) = 0 -> TRUE | AE15: =SUMPRODUCT((F15:AA15 - $F$2:$AA$2) * ((F15:AA15 - $F$2:$AA$2) > 0)) -> 0 | AJ15: Cook's Assistant | AK15: =IFERROR(ADDRESS(MATCH(AJ15, $A$5:$A$180, 0) + 4, COLUMN(A11)), "Not Found") -> $A$15
A16: Creature of Fenkenstrain | B16: =AND(D16=TRUE(),E16=TRUE()) -> FALSE | C16: Y | D16: =TRUE() -> TRUE | E16: =SUMPRODUCT((F16:AD16 <> "") * (F16:AD16 < F$2:AD$2)) = 1 -> FALSE | J16: 20 | AA16: 25 | AE16: =SUMPRODUCT((F16:AA16 - $F$2:$AA$2) * ((F16:AA16 - $F$2:$AA$2) > 0)) -> 0 | AJ16: Creature of Fenkenstrain | AK16: =IFERROR(ADDRESS(MATCH(AJ16, $A$5:$A$180, 0) + 4, COLUMN(A12)), "Not Found") -> $A$16
A17: Darkness of Hallowvale | B17: =AND(D17=TRUE(),E17=TRUE()) -> FALSE | C17: N | D17: =AND(INDEX(C:C, MATCH("In Aid of the Myreque", AJ:AJ, 0)) = "Y") -> FALSE | E17: =SUMPRODUCT((F17:AD17 <> "") * (F17:AD17 < F$2:AD$2)) = 7 -> TRUE | F17: 26 | H17: 5 | J17: 32 | R17: 33 | S17: 20 | Z17: 40 | AA17: 22 | AE17: =SUMPRODUCT((F17:AA17 - $F$2:$AA$2) * ((F17:AA17 - $F$2:$AA$2) > 0)) -> 0 | AJ17: Darkness of Hallowvale | AK17: =IFERROR(ADDRESS(MATCH(AJ17, $A$5:$A$180, 0) + 4, COLUMN(A13)), "Not Found") -> $A$17
A18: Death Plateau | B18: =AND(D18=TRUE(),E18=TRUE()) -> TRUE | C18: Y | D18: =TRUE() -> TRUE | E18: =SUMPRODUCT((F18:AD18 <> "") * (F18:AD18 < F$2:AD$2)) = 0 -> TRUE | AE18: =SUMPRODUCT((F18:AA18 - $F$2:$AA$2) * ((F18:AA18 - $F$2:$AA$2) > 0)) -> 0 | AJ18: Death Plateau | AK18: =IFERROR(ADDRESS(MATCH(AJ18, $A$5:$A$180, 0) + 4, COLUMN(A14)), "Not Found") -> $A$18
A19: Death to the Dorgeshuun | B19: =AND(D19=TRUE(),E19=TRUE()) -> FALSE | C19: N | D19: =AND(INDEX(C:C, MATCH("Lost Tribe, The" , AJ:AJ, 0)) = "Y") -> FALSE | E19: =SUMPRODUCT((F19:AD19 <> "") * (F19:AD19 < F$2:AD$2)) = 2 -> TRUE | F19: 23 | AA19: 23 | AE19: =SUMPRODUCT((F19:AA19 - $F$2:$AA$2) * ((F19:AA19 - $F$2:$AA$2) > 0)) -> 0 | AJ19: Death to the Dorgeshuun | AK19: =IFERROR(ADDRESS(MATCH(AJ19, $A$5:$A$180, 0) + 4, COLUMN(A15)), "Not Found") -> $A$19
A20: Demon Slayer | B20: =AND(D20=TRUE(),E20=TRUE()) -> TRUE | C20: Y | D20: =TRUE() -> TRUE | E20: =SUMPRODUCT((F20:AD20 <> "") * (F20:AD20 < F$2:AD$2)) = 0 -> TRUE | AE20: =SUMPRODUCT((F20:AA20 - $F$2:$AA$2) * ((F20:AA20 - $F$2:$AA$2) > 0)) -> 0 | AJ20: Demon Slayer | AK20: =IFERROR(ADDRESS(MATCH(AJ20, $A$5:$A$180, 0) + 4, COLUMN(A16)), "Not Found") -> $A$20
A21: Desert Treasure | B21: =AND(D21=TRUE(),E21=TRUE()) -> TRUE | C21: Y | D21: =TRUE() -> TRUE | E21: =SUMPRODUCT((F21:AD21 <> "") * (F21:AD21 < F$2:AD$2)) = 4 -> 1 | M21: 50 | R21: 50 | X21: 10 | AA21: 53 | AE21: =SUMPRODUCT((F21:AA21 - $F$2:$AA$2) * ((F21:AA21 - $F$2:$AA$2) > 0)) -> 0 | AJ21: Desert Treasure | AK21: =IFERROR(ADDRESS(MATCH(AJ21, $A$5:$A$180, 0) + 4, COLUMN(A17)), "Not Found") -> $A$21
A22: Devious Minds | B22: =AND(D22=TRUE(),E22=TRUE()) -> FALSE | C22: N | D22: =AND(INDEX(C:C, MATCH("Wanted!", AJ:AJ, 0)) = "Y",INDEX(C:C, MATCH("Troll Stronghold", AJ:AJ, 0)) = "Y",INDEX(C:C, MATCH("Doric's Quest", AJ:AJ, 0)) = "Y",INDEX(C:C, MATCH("Wanted!", AJ:AJ, 0)) = "Y",INDEX(C:C, MATCH("Recruitment Drive", AJ:AJ, 0)) = "Y") -> FALSE | E22: =SUMPRODUCT((F22:AD22 <> "") * (F22:AD22 < F$2:AD$2)) = 3 -> FALSE | O22: 50 | V22: 50 | Y22: 65 | AE22: =SUMPRODUCT((F22:AA22 - $F$2:$AA$2) * ((F22:AA22 - $F$2:$AA$2) > 0)) -> 39 | AJ22: Devious Minds | AK22: =IFERROR(ADDRESS(MATCH(AJ22, $A$5:$A$180, 0) + 4, COLUMN(A18)), "Not Found") -> $A$22
A23: Digsite, The | B23: =AND(D23=TRUE(),E23=TRUE()) -> TRUE | C23: Y | D23: =TRUE() -> TRUE | E23: =SUMPRODUCT((F23:AD23 <> "") * (F23:AD23 < F$2:AD$2)) = 3 -> TRUE | F23: 10 | P23: 10 | AA23: 25 | AE23: =SUMPRODUCT((F23:AA23 - $F$2:$AA$2) * ((F23:AA23 - $F$2:$AA$2) > 0)) -> 0 | AJ23: Digsite, The | AK23: =IFERROR(ADDRESS(MATCH(AJ23, $A$5:$A$180, 0) + 4, COLUMN(A19)), "Not Found") -> $A$23
A24: Doric's Quest | B24: =AND(D24=TRUE(),E24=TRUE()) -> TRUE | C24: Y | D24: =TRUE() -> TRUE | E24: =SUMPRODUCT((F24:AD24 <> "") * (F24:AD24 < F$2:AD$2)) = 1 -> TRUE | S24: 15 | AE24: =SUMPRODUCT((F24:AA24 - $F$2:$AA$2) * ((F24:AA24 - $F$2:$AA$2) > 0)) -> 0 | AJ24: Doric's Quest | AK24: =IFERROR(ADDRESS(MATCH(AJ24, $A$5:$A$180, 0) + 4, COLUMN(A20)), "Not Found") -> $A$24
A25: Dragon Slayer | B25: =AND(D25=TRUE(),E25=TRUE()) -> TRUE | C25: Y | D25: =TRUE() -> TRUE | E25: =SUMPRODUCT((F25:AD25 <> "") * (F25:AD25 < F$2:AD$2)) = 2 -> TRUE | R25: 33 | AC25: 32 | AE25: =SUMPRODUCT((F25:AA25 - $F$2:$AA$2) * ((F25:AA25 - $F$2:$AA$2) > 0)) -> 0 | AJ25: Dragon Slayer | AK25: =IFERROR(ADDRESS(MATCH(AJ25, $A$5:$A$180, 0) + 4, COLUMN(A21)), "Not Found") -> $A$25
A26: Dream Mentor | B26: =AND(D26=TRUE(),E26=TRUE()) -> FALSE | C26: N | D26: =AND(INDEX(C:C, MATCH("Lunar Diplomacy", AJ:AJ, 0)) = "Y",INDEX(C:C, MATCH("Eadgar's Ruse", AJ:AJ, 0)) = "Y") -> FALSE | E26: =SUMPRODUCT((F26:AD26 <> "") * (F26:AD26 < F$2:AD$2)) = 1 -> TRUE | AD26: 85 | AE26: =SUMPRODUCT((F26:AA26 - $F$2:$AA$2) * ((F26:AA26 - $F$2:$AA$2) > 0)) -> 0 | AJ26: Dream Mentor | AK26: =IFERROR(ADDRESS(MATCH(AJ26, $A$5:$A$180, 0) + 4, COLUMN(A22)), "Not Found") -> $A$26
A27: Druidic Ritual | B27: =AND(D27=TRUE(),E27=TRUE()) -> TRUE | C27: Y | D27: =TRUE() -> TRUE | E27: =SUMPRODUCT((F27:AD27 <> "") * (F27:AD27 < F$2:AD$2)) = 0 -> TRUE | AE27: =SUMPRODUCT((F27:AA27 - $F$2:$AA$2) * ((F27:AA27 - $F$2:$AA$2) > 0)) -> 0 | AJ27: Druidic Ritual | AK27: =IFERROR(ADDRESS(MATCH(AJ27, $A$5:$A$180, 0) + 4, COLUMN(A23)), "Not Found") -> $A$27
A28: Dwarf Cannon | B28: =AND(D28=TRUE(),E28=TRUE()) -> TRUE | C28: Y | D28: =TRUE() -> TRUE | E28: =SUMPRODUCT((F28:AD28 <> "") * (F28:AD28 < F$2:AD$2)) = 1 -> TRUE | F28: 20 | AE28: =SUMPRODUCT((F28:AA28 - $F$2:$AA$2) * ((F28:AA28 - $F$2:$AA$2) > 0)) -> 0 | AJ28: Dwarf Cannon | AK28: =IFERROR(ADDRESS(MATCH(AJ28, $A$5:$A$180, 0) + 4, COLUMN(A24)), "Not Found") -> $A$28
A29: Eadgar's Ruse | B29: =AND(D29=TRUE(),E29=TRUE()) -> TRUE | C29: N | D29: =AND(INDEX(C:C, MATCH("Druidic Ritual", AJ:AJ, 0)) = "Y",INDEX(C:C, MATCH("Troll Stronghold", AJ:AJ, 0)) = "Y") -> TRUE | E29: =SUMPRODUCT((F29:AD29 <> "") * (F29:AD29 < F$2:AD$2)) = 2 -> TRUE | F29: 43 | P29: 31 | AE29: =SUMPRODUCT((F29:AA29 - $F$2:$AA$2) * ((F29:AA29 - $F$2:$AA$2) > 0)) -> 0 | AJ29: Eadgar's Ruse | AK29: =IFERROR(ADDRESS(MATCH(AJ29, $A$5:$A$180, 0) + 4, COLUMN(A25)), "Not Found") -> $A$29
A30: Eagles' Peak | B30: =AND(D30=TRUE(),E30=TRUE()) -> TRUE | C30: Y | D30: =TRUE() -> TRUE | E30: =SUMPRODUCT((F30:AD30 <> "") * (F30:AD30 < F$2:AD$2)) = 1 -> TRUE | Q30: 27 | AE30: =SUMPRODUCT((F30:AA30 - $F$2:$AA$2) * ((F30:AA30 - $F$2:$AA$2) > 0)) -> 0 | AJ30: Eagles' Peak | AK30: =IFERROR(ADDRESS(MATCH(AJ30, $A$5:$A$180, 0) + 4, COLUMN(A26)), "Not Found") -> $A$30
A31: Elemental Workshop I | B31: =AND(D31=TRUE(),E31=TRUE()) -> TRUE | C31: Y | D31: =TRUE() -> TRUE | E31: =SUMPRODUCT((F31:AD31 <> "") * (F31:AD31 < F$2:AD$2)) = 3 -> TRUE | J31: 20 | S31: 20 | Y31: 20 | AE31: =SUMPRODUCT((F31:AA31 - $F$2:$AA$2) * ((F31:AA31 - $F$2:$AA$2) > 0)) -> 0 | AJ31: Elemental Workshop I | AK31: =IFERROR(ADDRESS(MATCH(AJ31, $A$5:$A$180, 0) + 4, COLUMN(A27)), "Not Found") -> $A$31
A32: Elemental Workshop II | B32: =AND(D32=TRUE(),E32=TRUE()) -> TRUE | C32: Y | D32: =AND(INDEX(C:C, MATCH("Elemental Workshop I", AJ:AJ, 0)) = "Y") -> TRUE | E32: =SUMPRODUCT((F32:AD32 <> "") * (F32:AD32 < F$2:AD$2)) = 2 -> TRUE | R32: 20 | Y32: 30 | AE32: =SUMPRODUCT((F32:AA32 - $F$2:$AA$2) * ((F32:AA32 - $F$2:$AA$2) > 0)) -> 0 | AJ32: Elemental Workshop II | AK32: =IFERROR(ADDRESS(MATCH(AJ32, $A$5:$A$180, 0) + 4, COLUMN(A28)), "Not Found") -> $A$32
A33: Enakhra's Lament | B33: =AND(D33=TRUE(),E33=TRUE()) -> TRUE | C33: N | D33: =TRUE() -> TRUE | E33: =SUMPRODUCT((F33:AD33 <> "") * (F33:AD33 <= F$2:AD$2)) = 4 -> TRUE | J33: 50 | M33: 45 | R33: 39 | T33: 43 | AE33: =SUMPRODUCT((F33:AA33 - $F$2:$AA$2) * ((F33:AA33 - $F$2:$AA$2) > 0)) -> 0 | AJ33: Enakhra's Lament | AK33: =IFERROR(ADDRESS(MATCH(AJ33, $A$5:$A$180, 0) + 4, COLUMN(A29)), "Not Found") -> $A$33
A34: Enlightened Journey | B34: =AND(D34=TRUE(),E34=TRUE()) -> TRUE | C34: Y | D34: =TRUE() -> TRUE | E34: =SUMPRODUCT((F34:AD34 <> "") * (F34:AD34 <= F$2:AD$2)) = 4 -> 1 | J34: 36 | L34: 30 | M34: 20 | AC34: 20 | AE34: =SUMPRODUCT((F34:AA34 - $F$2:$AA$2) * ((F34:AA34 - $F$2:$AA$2) > 0)) -> 0 | AJ34: Enlightened Journey | AK34: =IFERROR(ADDRESS(MATCH(AJ34, $A$5:$A$180, 0) + 4, COLUMN(A30)), "Not Found") -> $A$34
A35: Ernest the Chicken | B35: =AND(D35=TRUE(),E35=TRUE()) -> TRUE | C35: Y | D35: =TRUE() -> TRUE | E35: =SUMPRODUCT((F35:AD35 <> "") * (F35:AD35 <= F$2:AD$2)) = 0 -> TRUE | AE35: =SUMPRODUCT((F35:AA35 - $F$2:$AA$2) * ((F35:AA35 - $F$2:$AA$2) > 0)) -> 0 | AJ35: Ernest the Chicken | AK35: =IFERROR(ADDRESS(MATCH(AJ35, $A$5:$A$180, 0) + 4, COLUMN(A31)), "Not Found") -> $A$35
A36: Eyes of Glouphrie, The | B36: =AND(D36=TRUE(),E36=TRUE()) -> TRUE | C36: N | D36: =AND(INDEX(C:C, MATCH("Grand Tree, The", AJ:AJ, 0)) = "Y") -> TRUE | E36: =SUMPRODUCT((F36:AD36 <> "") * (F36:AD36 <= F$2:AD$2)) = 2 -> TRUE | H36: 5 | R36: 46 | AE36: =SUMPRODUCT((F36:AA36 - $F$2:$AA$2) * ((F36:AA36 - $F$2:$AA$2) > 0)) -> 0 | AJ36: Eyes of Glouphrie, The | AK36: =IFERROR(ADDRESS(MATCH(AJ36, $A$5:$A$180, 0) + 4, COLUMN(A32)), "Not Found") -> $A$36
A37: Fairytale I | B37: =AND(D37=TRUE(),E37=TRUE()) -> TRUE | C37: Y | D37: =AND(INDEX(C:C, MATCH("Lost City", AJ:AJ, 0)) = "Y",INDEX(C:C, MATCH("Nature Spirit", AJ:AJ, 0)) = "Y") -> TRUE | E37: =SUMPRODUCT((F37:AD37 <> "") * (F37:AD37 <= F$2:AD$2)) = 0 -> TRUE | AE37: =SUMPRODUCT((F37:AA37 - $F$2:$AA$2) * ((F37:AA37 - $F$2:$AA$2) > 0)) -> 0 | AJ37: Fairytale I | AK37: =IFERROR(ADDRESS(MATCH(AJ37, $A$5:$A$180, 0) + 4, COLUMN(A33)), "Not Found") -> $A$37
A38: Fairytale II | B38: =AND(D38=TRUE(),E38=TRUE()) -> FALSE | C38: N | D38: =AND(INDEX(C:C, MATCH("Fairytale I", AJ:AJ, 0)) = "Y") -> TRUE | E38: =SUMPRODUCT((F38:AD38 <> "") * (F38:AD38 <= F$2:AD$2)) = 3 -> FALSE | L38: 49 | P38: 57 | AA38: 40 | AE38: =SUMPRODUCT((F38:AA38 - $F$2:$AA$2) * ((F38:AA38 - $F$2:$AA$2) > 0)) -> 3 | AJ38: Fairytale II | AK38: =IFERROR(ADDRESS(MATCH(AJ38, $A$5:$A$180, 0) + 4, COLUMN(A34)), "Not Found") -> $A$38
A39: Family Crest | B39: =AND(D39=TRUE(),E39=TRUE()) -> TRUE | C39: Y | D39: =TRUE() -> TRUE | E39: =SUMPRODUCT((F39:AD39 <> "") * (F39:AD39 <= F$2:AD$2)) = 4 -> 1 | J39: 40 | R39: 59 | S39: 40 | Y39: 40 | AE39: =SUMPRODUCT((F39:AA39 - $F$2:$AA$2) * ((F39:AA39 - $F$2:$AA$2) > 0)) -> 0 | AJ39: Family Crest | AK39: =IFERROR(ADDRESS(MATCH(AJ39, $A$5:$A$180, 0) + 4, COLUMN(A35)), "Not Found") -> $A$39
A40: Feud, The | B40: =AND(D40=TRUE(),E40=TRUE()) -> TRUE | C40: Y | D40: =TRUE() -> TRUE | E40: =SUMPRODUCT((F40:AD40 <> "") * (F40:AD40 <= F$2:AD$2)) = 1 -> TRUE | AA40: 30 | AE40: =SUMPRODUCT((F40:AA40 - $F$2:$AA$2) * ((F40:AA40 - $F$2:$AA$2) > 0)) -> 0 | AJ40: Feud, The | AK40: =IFERROR(ADDRESS(MATCH(AJ40, $A$5:$A$180, 0) + 4, COLUMN(A36)), "Not Found") -> $A$40
A41: Fight Arena | B41: =AND(D41=TRUE(),E41=TRUE()) -> TRUE | C41: Y | D41: =TRUE() -> TRUE | E41: =SUMPRODUCT((F41:AD41 <> "") * (F41:AD41 <= F$2:AD$2)) = 0 -> TRUE | AE41: =SUMPRODUCT((F41:AA41 - $F$2:$AA$2) * ((F41:AA41 - $F$2:$AA$2) > 0)) -> 0 | AJ41: Fight Arena | AK41: =IFERROR(ADDRESS(MATCH(AJ41, $A$5:$A$180, 0) + 4, COLUMN(A37)), "Not Found") -> $A$41
...

Sheet Form Responses 1

Sheet Sheet4
A1: Animal Magnetism | B1: =TRUE() -> 1 | C1: Y | E1: Animal Magnetism | F1: =TRUE() -> 1 | G1: Y
A2: Another Slice of H.A.M. | B2: =FALSE() -> 0 | C2: N | E2: Another Slice of H.A.M. | F2: =TRUE() -> 1 | G2: N
A3: Ascent of Arceuus, The | B3: =FALSE() -> 0 | C3: N | E3: Ascent of Arceuus, The | F3: =FALSE() -> 0 | G3: N
A4: At First Light | B4: =FALSE() -> 0 | C4: N | E4: At First Light | F4: =FALSE() -> 0 | G4: N
A5: Below Ice Mountain | B5: =TRUE() -> 1 | C5: Y | E5: Below Ice Mountain | F5: =TRUE() -> 1 | G5: Y
A6: Beneath Cursed Sands | B6: =FALSE() -> 0 | C6: N | E6: Beneath Cursed Sands | F6: =FALSE() -> 0 | G6: N
A7: Between a Rock… | B7: =TRUE() -> 1 | C7: Y | E7: Between a Rock… | F7: =FALSE() -> 0 | G7: Y
A8: Big Chompy Bird Hunting | B8: =TRUE() -> 1 | C8: Y | E8: Big Chompy Bird Hunting | F8: =TRUE() -> 1 | G8: Y
A9: Black Knight's Fortress | B9: =TRUE() -> 1 | C9: Y | E9: Black Knight's Fortress | F9: =FALSE() -> 0 | G9: Y
A10: Black Knight's Fortress | B10: =TRUE() -> 1 | C10: Y | E10: Black Knight's Fortress | F10: =TRUE() -> 1 | G10: Y
A11: Bone Voyage | B11: =TRUE() -> 1 | C11: Y | E11: Bone Voyage | F11: =TRUE() -> 1 | G11: Y
A12: Cabin Fever | B12: =TRUE() -> 1 | C12: Y | E12: Cabin Fever | F12: =TRUE() -> 1 | G12: Y
A13: Children of the Sun | B13: =TRUE() -> 1 | C13: Y | E13: Children of the Sun | F13: =TRUE() -> 1 | G13: Y
A14: Client of Kourend | B14: =TRUE() -> 1 | C14: Y | E14: Client of Kourend | F14: =TRUE() -> 1 | G14: Y
A15: Clock Tower | B15: =TRUE() -> 1 | C15: Y | E15: Clock Tower | F15: =TRUE() -> 1 | G15: Y
A16: Cold War | B16: =TRUE() -> 1 | C16: N | E16: Cold War | F16: =TRUE() -> 1 | G16: N
A17: Contact! | B17: =TRUE() -> 1 | C17: N | E17: Contact! | F17: =TRUE() -> 1 | G17: N
A18: Cook's Assistant | B18: =TRUE() -> 1 | C18: Y | E18: Cook's Assistant | F18: =TRUE() -> 1 | G18: Y
A19: Creature of Fenkenstrain | B19: =TRUE() -> 1 | C19: Y | E19: Creature of Fenkenstrain | F19: =TRUE() -> 1 | G19: Y
A20: Current Affairs | B20: =TRUE() -> 1 | C20: Y | E20: Current Affairs | F20: #REF! | G20: Y
A21: Curse of Arrav, The | B21: =TRUE() -> 1 | C21: Y | E21: Curse of Arrav, The | F21: =TRUE() -> 1 | G21: Y
A22: Curse of Arrav, The | B22: =FALSE() -> 0 | C22: N | E22: Curse of Arrav, The | F22: =FALSE() -> 0 | G22: N
A23: Darkness of Hallowvale | B23: =FALSE() -> 0 | C23: N | E23: Darkness of Hallowvale | F23: =FALSE() -> 0 | G23: N
A24: Death on the Isle | B24: =TRUE() -> 1 | C24: N | E24: Death on the Isle | F24: =TRUE() -> 1 | G24: N
A25: Death Plateau | B25: =TRUE() -> 1 | C25: Y | E25: Death Plateau | F25: =TRUE() -> 1 | G25: Y
A26: Death to the Dorgeshuun | B26: =FALSE() -> 0 | C26: N | E26: Death to the Dorgeshuun | F26: =TRUE() -> 1 | G26: N
A27: Defender of Varrock | B27: =FALSE() -> 0 | C27: N | E27: Defender of Varrock | F27: =FALSE() -> 0 | G27: N
A28: Demon Slayer | B28: =TRUE() -> 1 | C28: Y | E28: Demon Slayer | F28: =TRUE() -> 1 | G28: Y
A29: Depths of Despair, The | B29: =TRUE() -> 1 | C29: Y | E29: Depths of Despair, The | F29: =TRUE() -> 1 | G29: Y
A30: Desert Treasure | B30: =TRUE() -> 1 | C30: Y | E30: Desert Treasure | F30: =TRUE() -> 1 | G30: Y
A31: Desert Treasure II | B31: =FALSE() -> 0 | C31: N | E31: Desert Treasure II | F31: =FALSE() -> 0 | G31: N
A32: Devious Minds | B32: =FALSE() -> 0 | C32: N | E32: Devious Minds | F32: =FALSE() -> 0 | G32: N
A33: Digsite, The | B33: =TRUE() -> 1 | C33: Y | E33: Digsite, The | F33: =TRUE() -> 1 | G33: Y
A34: Doric's Quest | B34: =TRUE() -> 1 | C34: Y | E34: Doric's Quest | F34: =TRUE() -> 1 | G34: Y
A35: Dragon Slayer | B35: =TRUE() -> 1 | C35: Y | E35: Dragon Slayer | F35: =TRUE() -> 1 | G35: Y
A36: Dragon Slayer II | B36: =FALSE() -> 0 | C36: N | E36: Dragon Slayer II | F36: =FALSE() -> 0 | G36: N
A37: Dream Mentor | B37: =FALSE() -> 0 | C37: N | E37: Dream Mentor | F37: =FALSE() -> 0 | G37: N
A38: Druidic Ritual | B38: =TRUE() -> 1 | C38: Y | E38: Druidic Ritual | F38: =TRUE() -> 1 | G38: Y
A39: Dwarf Cannon | B39: =TRUE() -> 1 | C39: Y | E39: Dwarf Cannon | F39: =TRUE() -> 1 | G39: Y
A40: Eadgar's Ruse | B40: =TRUE() -> 1 | C40: N | E40: Eadgar's Ruse | F40: =FALSE() -> 0 | G40: N
...
